[2024-10-31T12:06:40.458+0100] {taskinstance.py:1087} INFO - Dependencies all met for <TaskInstance: airbyte_sync_dag.trigger_airbyte_sync scheduled__2024-10-31T10:00:00+00:00 [queued]>
[2024-10-31T12:06:40.484+0100] {taskinstance.py:1087} INFO - Dependencies all met for <TaskInstance: airbyte_sync_dag.trigger_airbyte_sync scheduled__2024-10-31T10:00:00+00:00 [queued]>
[2024-10-31T12:06:40.484+0100] {taskinstance.py:1283} INFO - 
--------------------------------------------------------------------------------
[2024-10-31T12:06:40.484+0100] {taskinstance.py:1284} INFO - Starting attempt 1 of 2
[2024-10-31T12:06:40.484+0100] {taskinstance.py:1285} INFO - 
--------------------------------------------------------------------------------
[2024-10-31T12:06:40.514+0100] {taskinstance.py:1304} INFO - Executing <Task(AirbyteTriggerSyncOperator): trigger_airbyte_sync> on 2024-10-31 10:00:00+00:00
[2024-10-31T12:06:40.523+0100] {standard_task_runner.py:55} INFO - Started process 212 to run task
[2024-10-31T12:06:40.530+0100] {standard_task_runner.py:82} INFO - Running: ['***', 'tasks', 'run', 'airbyte_sync_dag', 'trigger_airbyte_sync', 'scheduled__2024-10-31T10:00:00+00:00', '--job-id', '49', '--raw', '--subdir', 'DAGS_FOLDER/airbyte_dag.py', '--cfg-path', '/tmp/tmpobst5aas']
[2024-10-31T12:06:40.534+0100] {standard_task_runner.py:83} INFO - Job 49: Subtask trigger_airbyte_sync
[2024-10-31T12:06:40.674+0100] {task_command.py:389} INFO - Running <TaskInstance: airbyte_sync_dag.trigger_airbyte_sync scheduled__2024-10-31T10:00:00+00:00 [running]> on host 5558cd404a6f
[2024-10-31T12:06:40.835+0100] {taskinstance.py:1513} INFO - Exporting the following env vars:
AIRFLOW_CTX_DAG_OWNER=Admin
AIRFLOW_CTX_DAG_ID=airbyte_sync_dag
AIRFLOW_CTX_TASK_ID=trigger_airbyte_sync
AIRFLOW_CTX_EXECUTION_DATE=2024-10-31T10:00:00+00:00
AIRFLOW_CTX_TRY_NUMBER=1
AIRFLOW_CTX_DAG_RUN_ID=scheduled__2024-10-31T10:00:00+00:00
[2024-10-31T12:06:40.854+0100] {base.py:73} INFO - Using connection ID 'airbyte_conn' for task execution.
[2024-10-31T12:06:40.862+0100] {http.py:150} INFO - Sending 'POST' to url: http://10.132.0.2:8000/api/v1/connections/sync
[2024-10-31T12:06:41.436+0100] {http.py:163} ERROR - HTTP error: Unauthorized
[2024-10-31T12:06:41.437+0100] {http.py:164} ERROR - {"message":"Unauthorized","_embedded":{"errors":[{"message":"Unauthorized","_embedded":{},"_links":{}}]},"_links":{"self":{"href":"/api/v1/connections/sync","templated":false}}}
[2024-10-31T12:06:41.479+0100] {taskinstance.py:1772} ERROR - Task failed with exception
Traceback (most recent call last):
  File "/home/airflow/.local/lib/python3.7/site-packages/airflow/providers/http/hooks/http.py", line 161, in check_response
    response.raise_for_status()
  File "/home/airflow/.local/lib/python3.7/site-packages/requests/models.py", line 1021, in raise_for_status
    raise HTTPError(http_error_msg, response=self)
requests.exceptions.HTTPError: 401 Client Error: Unauthorized for url: http://10.132.0.2:8000/api/v1/connections/sync

During handling of the above exception, another exception occurred:

Traceback (most recent call last):
  File "/home/airflow/.local/lib/python3.7/site-packages/airflow/providers/airbyte/operators/airbyte.py", line 74, in execute
    job_object = self.hook.submit_sync_connection(connection_id=self.connection_id)
  File "/home/airflow/.local/lib/python3.7/site-packages/airflow/providers/airbyte/hooks/airbyte.py", line 95, in submit_sync_connection
    headers={"accept": "application/json"},
  File "/home/airflow/.local/lib/python3.7/site-packages/airflow/providers/http/hooks/http.py", line 151, in run
    return self.run_and_check(session, prepped_request, extra_options)
  File "/home/airflow/.local/lib/python3.7/site-packages/airflow/providers/http/hooks/http.py", line 204, in run_and_check
    self.check_response(response)
  File "/home/airflow/.local/lib/python3.7/site-packages/airflow/providers/http/hooks/http.py", line 165, in check_response
    raise AirflowException(str(response.status_code) + ":" + response.reason)
airflow.exceptions.AirflowException: 401:Unauthorized
[2024-10-31T12:06:41.495+0100] {taskinstance.py:1327} INFO - Marking task as UP_FOR_RETRY. dag_id=airbyte_sync_dag, task_id=trigger_airbyte_sync, execution_date=20241031T100000, start_date=20241031T110640, end_date=20241031T110641
[2024-10-31T12:06:41.527+0100] {standard_task_runner.py:105} ERROR - Failed to execute job 49 for task trigger_airbyte_sync (401:Unauthorized; 212)
[2024-10-31T12:06:41.551+0100] {local_task_job.py:159} INFO - Task exited with return code 1
[2024-10-31T12:06:41.675+0100] {taskinstance.py:2582} INFO - 0 downstream tasks scheduled from follow-on schedule check
