[2024-10-28T17:23:30.150+0100] {taskinstance.py:1087} INFO - Dependencies all met for <TaskInstance: airbyte_dag.run_airbyte_container scheduled__2024-10-28T15:00:00+00:00 [queued]>
[2024-10-28T17:23:30.187+0100] {taskinstance.py:1087} INFO - Dependencies all met for <TaskInstance: airbyte_dag.run_airbyte_container scheduled__2024-10-28T15:00:00+00:00 [queued]>
[2024-10-28T17:23:30.188+0100] {taskinstance.py:1283} INFO - 
--------------------------------------------------------------------------------
[2024-10-28T17:23:30.188+0100] {taskinstance.py:1284} INFO - Starting attempt 1 of 2
[2024-10-28T17:23:30.188+0100] {taskinstance.py:1285} INFO - 
--------------------------------------------------------------------------------
[2024-10-28T17:23:30.219+0100] {taskinstance.py:1304} INFO - Executing <Task(DockerOperator): run_airbyte_container> on 2024-10-28 15:00:00+00:00
[2024-10-28T17:23:30.234+0100] {standard_task_runner.py:55} INFO - Started process 1006 to run task
[2024-10-28T17:23:30.245+0100] {standard_task_runner.py:82} INFO - Running: ['***', 'tasks', 'run', 'airbyte_dag', 'run_airbyte_container', 'scheduled__2024-10-28T15:00:00+00:00', '--job-id', '5', '--raw', '--subdir', 'DAGS_FOLDER/airbyte_dag.py', '--cfg-path', '/tmp/tmpr5uk5j5i']
[2024-10-28T17:23:30.250+0100] {standard_task_runner.py:83} INFO - Job 5: Subtask run_airbyte_container
[2024-10-28T17:23:30.445+0100] {task_command.py:389} INFO - Running <TaskInstance: airbyte_dag.run_airbyte_container scheduled__2024-10-28T15:00:00+00:00 [running]> on host e26da35bf80a
[2024-10-28T17:23:30.631+0100] {taskinstance.py:1513} INFO - Exporting the following env vars:
AIRFLOW_CTX_DAG_OWNER=***
AIRFLOW_CTX_DAG_ID=airbyte_dag
AIRFLOW_CTX_TASK_ID=run_airbyte_container
AIRFLOW_CTX_EXECUTION_DATE=2024-10-28T15:00:00+00:00
AIRFLOW_CTX_TRY_NUMBER=1
AIRFLOW_CTX_DAG_RUN_ID=scheduled__2024-10-28T15:00:00+00:00
[2024-10-28T17:23:30.638+0100] {taskinstance.py:1772} ERROR - Task failed with exception
Traceback (most recent call last):
  File "/home/airflow/.local/lib/python3.7/site-packages/urllib3/connectionpool.py", line 710, in urlopen
    chunked=chunked,
  File "/home/airflow/.local/lib/python3.7/site-packages/urllib3/connectionpool.py", line 398, in _make_request
    conn.request(method, url, **httplib_request_kw)
  File "/usr/local/lib/python3.7/http/client.py", line 1281, in request
    self._send_request(method, url, body, headers, encode_chunked)
  File "/usr/local/lib/python3.7/http/client.py", line 1327, in _send_request
    self.endheaders(body, encode_chunked=encode_chunked)
  File "/usr/local/lib/python3.7/http/client.py", line 1276, in endheaders
    self._send_output(message_body, encode_chunked=encode_chunked)
  File "/usr/local/lib/python3.7/http/client.py", line 1036, in _send_output
    self.send(msg)
  File "/usr/local/lib/python3.7/http/client.py", line 976, in send
    self.connect()
  File "/home/airflow/.local/lib/python3.7/site-packages/docker/transport/unixconn.py", line 30, in connect
    sock.connect(self.unix_socket)
FileNotFoundError: [Errno 2] No such file or directory

During handling of the above exception, another exception occurred:

Traceback (most recent call last):
  File "/home/airflow/.local/lib/python3.7/site-packages/requests/adapters.py", line 499, in send
    timeout=timeout,
  File "/home/airflow/.local/lib/python3.7/site-packages/urllib3/connectionpool.py", line 788, in urlopen
    method, url, error=e, _pool=self, _stacktrace=sys.exc_info()[2]
  File "/home/airflow/.local/lib/python3.7/site-packages/urllib3/util/retry.py", line 550, in increment
    raise six.reraise(type(error), error, _stacktrace)
  File "/home/airflow/.local/lib/python3.7/site-packages/urllib3/packages/six.py", line 769, in reraise
    raise value.with_traceback(tb)
  File "/home/airflow/.local/lib/python3.7/site-packages/urllib3/connectionpool.py", line 710, in urlopen
    chunked=chunked,
  File "/home/airflow/.local/lib/python3.7/site-packages/urllib3/connectionpool.py", line 398, in _make_request
    conn.request(method, url, **httplib_request_kw)
  File "/usr/local/lib/python3.7/http/client.py", line 1281, in request
    self._send_request(method, url, body, headers, encode_chunked)
  File "/usr/local/lib/python3.7/http/client.py", line 1327, in _send_request
    self.endheaders(body, encode_chunked=encode_chunked)
  File "/usr/local/lib/python3.7/http/client.py", line 1276, in endheaders
    self._send_output(message_body, encode_chunked=encode_chunked)
  File "/usr/local/lib/python3.7/http/client.py", line 1036, in _send_output
    self.send(msg)
  File "/usr/local/lib/python3.7/http/client.py", line 976, in send
    self.connect()
  File "/home/airflow/.local/lib/python3.7/site-packages/docker/transport/unixconn.py", line 30, in connect
    sock.connect(self.unix_socket)
urllib3.exceptions.ProtocolError: ('Connection aborted.', FileNotFoundError(2, 'No such file or directory'))

During handling of the above exception, another exception occurred:

Traceback (most recent call last):
  File "/home/airflow/.local/lib/python3.7/site-packages/docker/api/client.py", line 214, in _retrieve_server_version
    return self.version(api_version=False)["ApiVersion"]
  File "/home/airflow/.local/lib/python3.7/site-packages/docker/api/daemon.py", line 181, in version
    return self._result(self._get(url), json=True)
  File "/home/airflow/.local/lib/python3.7/site-packages/docker/utils/decorators.py", line 46, in inner
    return f(self, *args, **kwargs)
  File "/home/airflow/.local/lib/python3.7/site-packages/docker/api/client.py", line 237, in _get
    return self.get(url, **self._set_request_timeout(kwargs))
  File "/home/airflow/.local/lib/python3.7/site-packages/requests/sessions.py", line 600, in get
    return self.request("GET", url, **kwargs)
  File "/home/airflow/.local/lib/python3.7/site-packages/requests/sessions.py", line 587, in request
    resp = self.send(prep, **send_kwargs)
  File "/home/airflow/.local/lib/python3.7/site-packages/requests/sessions.py", line 701, in send
    r = adapter.send(request, **kwargs)
  File "/home/airflow/.local/lib/python3.7/site-packages/requests/adapters.py", line 547, in send
    raise ConnectionError(err, request=request)
requests.exceptions.ConnectionError: ('Connection aborted.', FileNotFoundError(2, 'No such file or directory'))

During handling of the above exception, another exception occurred:

Traceback (most recent call last):
  File "/home/airflow/.local/lib/python3.7/site-packages/airflow/providers/docker/operators/docker.py", line 407, in execute
    self.cli = self._get_cli()
  File "/home/airflow/.local/lib/python3.7/site-packages/airflow/providers/docker/operators/docker.py", line 438, in _get_cli
    base_url=self.docker_url, version=self.api_version, tls=tls_config, timeout=self.timeout
  File "/home/airflow/.local/lib/python3.7/site-packages/docker/api/client.py", line 197, in __init__
    self._version = self._retrieve_server_version()
  File "/home/airflow/.local/lib/python3.7/site-packages/docker/api/client.py", line 222, in _retrieve_server_version
    f'Error while fetching server API version: {e}'
docker.errors.DockerException: Error while fetching server API version: ('Connection aborted.', FileNotFoundError(2, 'No such file or directory'))
[2024-10-28T17:23:30.655+0100] {taskinstance.py:1327} INFO - Marking task as UP_FOR_RETRY. dag_id=airbyte_dag, task_id=run_airbyte_container, execution_date=20241028T150000, start_date=20241028T162330, end_date=20241028T162330
[2024-10-28T17:23:30.676+0100] {standard_task_runner.py:105} ERROR - Failed to execute job 5 for task run_airbyte_container (Error while fetching server API version: ('Connection aborted.', FileNotFoundError(2, 'No such file or directory')); 1006)
[2024-10-28T17:23:30.706+0100] {local_task_job.py:159} INFO - Task exited with return code 1
[2024-10-28T17:23:30.776+0100] {taskinstance.py:2582} INFO - 0 downstream tasks scheduled from follow-on schedule check
[2024-10-28T17:28:20.325+0100] {taskinstance.py:1087} INFO - Dependencies all met for <TaskInstance: airbyte_dag.run_airbyte_container scheduled__2024-10-28T15:00:00+00:00 [queued]>
[2024-10-28T17:28:20.352+0100] {taskinstance.py:1087} INFO - Dependencies all met for <TaskInstance: airbyte_dag.run_airbyte_container scheduled__2024-10-28T15:00:00+00:00 [queued]>
[2024-10-28T17:28:20.353+0100] {taskinstance.py:1283} INFO - 
--------------------------------------------------------------------------------
[2024-10-28T17:28:20.353+0100] {taskinstance.py:1284} INFO - Starting attempt 1 of 2
[2024-10-28T17:28:20.353+0100] {taskinstance.py:1285} INFO - 
--------------------------------------------------------------------------------
[2024-10-28T17:28:20.377+0100] {taskinstance.py:1304} INFO - Executing <Task(DockerOperator): run_airbyte_container> on 2024-10-28 15:00:00+00:00
[2024-10-28T17:28:20.385+0100] {standard_task_runner.py:55} INFO - Started process 6239 to run task
[2024-10-28T17:28:20.392+0100] {standard_task_runner.py:82} INFO - Running: ['***', 'tasks', 'run', 'airbyte_dag', 'run_airbyte_container', 'scheduled__2024-10-28T15:00:00+00:00', '--job-id', '7', '--raw', '--subdir', 'DAGS_FOLDER/airbyte_dag.py', '--cfg-path', '/tmp/tmp8zyhxpx7']
[2024-10-28T17:28:20.395+0100] {standard_task_runner.py:83} INFO - Job 7: Subtask run_airbyte_container
[2024-10-28T17:28:20.515+0100] {task_command.py:389} INFO - Running <TaskInstance: airbyte_dag.run_airbyte_container scheduled__2024-10-28T15:00:00+00:00 [running]> on host e26da35bf80a
[2024-10-28T17:28:20.640+0100] {taskinstance.py:1513} INFO - Exporting the following env vars:
AIRFLOW_CTX_DAG_OWNER=***
AIRFLOW_CTX_DAG_ID=airbyte_dag
AIRFLOW_CTX_TASK_ID=run_airbyte_container
AIRFLOW_CTX_EXECUTION_DATE=2024-10-28T15:00:00+00:00
AIRFLOW_CTX_TRY_NUMBER=1
AIRFLOW_CTX_DAG_RUN_ID=scheduled__2024-10-28T15:00:00+00:00
[2024-10-28T17:28:20.647+0100] {taskinstance.py:1772} ERROR - Task failed with exception
Traceback (most recent call last):
  File "/home/airflow/.local/lib/python3.7/site-packages/urllib3/connectionpool.py", line 710, in urlopen
    chunked=chunked,
  File "/home/airflow/.local/lib/python3.7/site-packages/urllib3/connectionpool.py", line 398, in _make_request
    conn.request(method, url, **httplib_request_kw)
  File "/usr/local/lib/python3.7/http/client.py", line 1281, in request
    self._send_request(method, url, body, headers, encode_chunked)
  File "/usr/local/lib/python3.7/http/client.py", line 1327, in _send_request
    self.endheaders(body, encode_chunked=encode_chunked)
  File "/usr/local/lib/python3.7/http/client.py", line 1276, in endheaders
    self._send_output(message_body, encode_chunked=encode_chunked)
  File "/usr/local/lib/python3.7/http/client.py", line 1036, in _send_output
    self.send(msg)
  File "/usr/local/lib/python3.7/http/client.py", line 976, in send
    self.connect()
  File "/home/airflow/.local/lib/python3.7/site-packages/docker/transport/unixconn.py", line 30, in connect
    sock.connect(self.unix_socket)
FileNotFoundError: [Errno 2] No such file or directory

During handling of the above exception, another exception occurred:

Traceback (most recent call last):
  File "/home/airflow/.local/lib/python3.7/site-packages/requests/adapters.py", line 499, in send
    timeout=timeout,
  File "/home/airflow/.local/lib/python3.7/site-packages/urllib3/connectionpool.py", line 788, in urlopen
    method, url, error=e, _pool=self, _stacktrace=sys.exc_info()[2]
  File "/home/airflow/.local/lib/python3.7/site-packages/urllib3/util/retry.py", line 550, in increment
    raise six.reraise(type(error), error, _stacktrace)
  File "/home/airflow/.local/lib/python3.7/site-packages/urllib3/packages/six.py", line 769, in reraise
    raise value.with_traceback(tb)
  File "/home/airflow/.local/lib/python3.7/site-packages/urllib3/connectionpool.py", line 710, in urlopen
    chunked=chunked,
  File "/home/airflow/.local/lib/python3.7/site-packages/urllib3/connectionpool.py", line 398, in _make_request
    conn.request(method, url, **httplib_request_kw)
  File "/usr/local/lib/python3.7/http/client.py", line 1281, in request
    self._send_request(method, url, body, headers, encode_chunked)
  File "/usr/local/lib/python3.7/http/client.py", line 1327, in _send_request
    self.endheaders(body, encode_chunked=encode_chunked)
  File "/usr/local/lib/python3.7/http/client.py", line 1276, in endheaders
    self._send_output(message_body, encode_chunked=encode_chunked)
  File "/usr/local/lib/python3.7/http/client.py", line 1036, in _send_output
    self.send(msg)
  File "/usr/local/lib/python3.7/http/client.py", line 976, in send
    self.connect()
  File "/home/airflow/.local/lib/python3.7/site-packages/docker/transport/unixconn.py", line 30, in connect
    sock.connect(self.unix_socket)
urllib3.exceptions.ProtocolError: ('Connection aborted.', FileNotFoundError(2, 'No such file or directory'))

During handling of the above exception, another exception occurred:

Traceback (most recent call last):
  File "/home/airflow/.local/lib/python3.7/site-packages/docker/api/client.py", line 214, in _retrieve_server_version
    return self.version(api_version=False)["ApiVersion"]
  File "/home/airflow/.local/lib/python3.7/site-packages/docker/api/daemon.py", line 181, in version
    return self._result(self._get(url), json=True)
  File "/home/airflow/.local/lib/python3.7/site-packages/docker/utils/decorators.py", line 46, in inner
    return f(self, *args, **kwargs)
  File "/home/airflow/.local/lib/python3.7/site-packages/docker/api/client.py", line 237, in _get
    return self.get(url, **self._set_request_timeout(kwargs))
  File "/home/airflow/.local/lib/python3.7/site-packages/requests/sessions.py", line 600, in get
    return self.request("GET", url, **kwargs)
  File "/home/airflow/.local/lib/python3.7/site-packages/requests/sessions.py", line 587, in request
    resp = self.send(prep, **send_kwargs)
  File "/home/airflow/.local/lib/python3.7/site-packages/requests/sessions.py", line 701, in send
    r = adapter.send(request, **kwargs)
  File "/home/airflow/.local/lib/python3.7/site-packages/requests/adapters.py", line 547, in send
    raise ConnectionError(err, request=request)
requests.exceptions.ConnectionError: ('Connection aborted.', FileNotFoundError(2, 'No such file or directory'))

During handling of the above exception, another exception occurred:

Traceback (most recent call last):
  File "/home/airflow/.local/lib/python3.7/site-packages/airflow/providers/docker/operators/docker.py", line 407, in execute
    self.cli = self._get_cli()
  File "/home/airflow/.local/lib/python3.7/site-packages/airflow/providers/docker/operators/docker.py", line 438, in _get_cli
    base_url=self.docker_url, version=self.api_version, tls=tls_config, timeout=self.timeout
  File "/home/airflow/.local/lib/python3.7/site-packages/docker/api/client.py", line 197, in __init__
    self._version = self._retrieve_server_version()
  File "/home/airflow/.local/lib/python3.7/site-packages/docker/api/client.py", line 222, in _retrieve_server_version
    f'Error while fetching server API version: {e}'
docker.errors.DockerException: Error while fetching server API version: ('Connection aborted.', FileNotFoundError(2, 'No such file or directory'))
[2024-10-28T17:28:20.662+0100] {taskinstance.py:1327} INFO - Marking task as UP_FOR_RETRY. dag_id=airbyte_dag, task_id=run_airbyte_container, execution_date=20241028T150000, start_date=20241028T162820, end_date=20241028T162820
[2024-10-28T17:28:20.681+0100] {standard_task_runner.py:105} ERROR - Failed to execute job 7 for task run_airbyte_container (Error while fetching server API version: ('Connection aborted.', FileNotFoundError(2, 'No such file or directory')); 6239)
[2024-10-28T17:28:20.724+0100] {local_task_job.py:159} INFO - Task exited with return code 1
[2024-10-28T17:28:20.788+0100] {taskinstance.py:2582} INFO - 0 downstream tasks scheduled from follow-on schedule check
