[2024-10-28T17:55:47.675+0100] {taskinstance.py:1087} INFO - Dependencies all met for <TaskInstance: airbyte_dag.run_airbyte_container manual__2024-10-28T16:50:43.254104+00:00 [queued]>
[2024-10-28T17:55:47.703+0100] {taskinstance.py:1087} INFO - Dependencies all met for <TaskInstance: airbyte_dag.run_airbyte_container manual__2024-10-28T16:50:43.254104+00:00 [queued]>
[2024-10-28T17:55:47.704+0100] {taskinstance.py:1283} INFO - 
--------------------------------------------------------------------------------
[2024-10-28T17:55:47.704+0100] {taskinstance.py:1284} INFO - Starting attempt 2 of 2
[2024-10-28T17:55:47.704+0100] {taskinstance.py:1285} INFO - 
--------------------------------------------------------------------------------
[2024-10-28T17:55:47.730+0100] {taskinstance.py:1304} INFO - Executing <Task(DockerOperator): run_airbyte_container> on 2024-10-28 16:50:43.254104+00:00
[2024-10-28T17:55:47.738+0100] {standard_task_runner.py:55} INFO - Started process 5557 to run task
[2024-10-28T17:55:47.745+0100] {standard_task_runner.py:82} INFO - Running: ['***', 'tasks', 'run', 'airbyte_dag', 'run_airbyte_container', 'manual__2024-10-28T16:50:43.254104+00:00', '--job-id', '17', '--raw', '--subdir', 'DAGS_FOLDER/airbyte_dag.py', '--cfg-path', '/tmp/tmpu_78u4mz']
[2024-10-28T17:55:47.748+0100] {standard_task_runner.py:83} INFO - Job 17: Subtask run_airbyte_container
[2024-10-28T17:55:47.859+0100] {task_command.py:389} INFO - Running <TaskInstance: airbyte_dag.run_airbyte_container manual__2024-10-28T16:50:43.254104+00:00 [running]> on host 0fa5b0a4899a
[2024-10-28T17:55:47.994+0100] {taskinstance.py:1513} INFO - Exporting the following env vars:
AIRFLOW_CTX_DAG_OWNER=***
AIRFLOW_CTX_DAG_ID=airbyte_dag
AIRFLOW_CTX_TASK_ID=run_airbyte_container
AIRFLOW_CTX_EXECUTION_DATE=2024-10-28T16:50:43.254104+00:00
AIRFLOW_CTX_TRY_NUMBER=2
AIRFLOW_CTX_DAG_RUN_ID=manual__2024-10-28T16:50:43.254104+00:00
[2024-10-28T17:55:48.019+0100] {docker.py:414} INFO - Pulling docker image airbyte/airbyte
[2024-10-28T17:55:49.058+0100] {taskinstance.py:1772} ERROR - Task failed with exception
Traceback (most recent call last):
  File "/home/airflow/.local/lib/python3.7/site-packages/docker/api/client.py", line 268, in _raise_for_status
    response.raise_for_status()
  File "/home/airflow/.local/lib/python3.7/site-packages/requests/models.py", line 1021, in raise_for_status
    raise HTTPError(http_error_msg, response=self)
requests.exceptions.HTTPError: 404 Client Error: Not Found for url: http+docker://localhost/v1.47/images/create?tag=latest&fromImage=airbyte%2Fairbyte

The above exception was the direct cause of the following exception:

Traceback (most recent call last):
  File "/home/airflow/.local/lib/python3.7/site-packages/airflow/providers/docker/operators/docker.py", line 416, in execute
    for output in self.cli.pull(self.image, stream=True, decode=True):
  File "/home/airflow/.local/lib/python3.7/site-packages/docker/api/image.py", line 429, in pull
    self._raise_for_status(response)
  File "/home/airflow/.local/lib/python3.7/site-packages/docker/api/client.py", line 270, in _raise_for_status
    raise create_api_error_from_http_exception(e) from e
  File "/home/airflow/.local/lib/python3.7/site-packages/docker/errors.py", line 39, in create_api_error_from_http_exception
    raise cls(e, response=response, explanation=explanation) from e
docker.errors.ImageNotFound: 404 Client Error for http+docker://localhost/v1.47/images/create?tag=latest&fromImage=airbyte%2Fairbyte: Not Found ("pull access denied for airbyte/airbyte, repository does not exist or may require 'docker login': denied: requested access to the resource is denied")
[2024-10-28T17:55:49.077+0100] {taskinstance.py:1327} INFO - Marking task as FAILED. dag_id=airbyte_dag, task_id=run_airbyte_container, execution_date=20241028T165043, start_date=20241028T165547, end_date=20241028T165549
[2024-10-28T17:55:49.103+0100] {standard_task_runner.py:105} ERROR - Failed to execute job 17 for task run_airbyte_container (404 Client Error for http+docker://localhost/v1.47/images/create?tag=latest&fromImage=airbyte%2Fairbyte: Not Found ("pull access denied for airbyte/airbyte, repository does not exist or may require 'docker login': denied: requested access to the resource is denied"); 5557)
[2024-10-28T17:55:49.120+0100] {local_task_job.py:159} INFO - Task exited with return code 1
[2024-10-28T17:55:49.199+0100] {taskinstance.py:2582} INFO - 0 downstream tasks scheduled from follow-on schedule check
