[2024-10-29T21:09:36.582+0100] {taskinstance.py:1087} INFO - Dependencies all met for <TaskInstance: airbyte_sync_dag.trigger_airbyte_sync scheduled__2024-10-29T19:00:00+00:00 [queued]>
[2024-10-29T21:09:36.609+0100] {taskinstance.py:1087} INFO - Dependencies all met for <TaskInstance: airbyte_sync_dag.trigger_airbyte_sync scheduled__2024-10-29T19:00:00+00:00 [queued]>
[2024-10-29T21:09:36.610+0100] {taskinstance.py:1283} INFO - 
--------------------------------------------------------------------------------
[2024-10-29T21:09:36.610+0100] {taskinstance.py:1284} INFO - Starting attempt 2 of 2
[2024-10-29T21:09:36.610+0100] {taskinstance.py:1285} INFO - 
--------------------------------------------------------------------------------
[2024-10-29T21:09:36.633+0100] {taskinstance.py:1304} INFO - Executing <Task(AirbyteTriggerSyncOperator): trigger_airbyte_sync> on 2024-10-29 19:00:00+00:00
[2024-10-29T21:09:36.646+0100] {standard_task_runner.py:55} INFO - Started process 8519 to run task
[2024-10-29T21:09:36.651+0100] {standard_task_runner.py:82} INFO - Running: ['***', 'tasks', 'run', 'airbyte_sync_dag', 'trigger_airbyte_sync', 'scheduled__2024-10-29T19:00:00+00:00', '--job-id', '38', '--raw', '--subdir', 'DAGS_FOLDER/airbyte_dag.py', '--cfg-path', '/tmp/tmplaitxbyb']
[2024-10-29T21:09:36.654+0100] {standard_task_runner.py:83} INFO - Job 38: Subtask trigger_airbyte_sync
[2024-10-29T21:09:36.767+0100] {task_command.py:389} INFO - Running <TaskInstance: airbyte_sync_dag.trigger_airbyte_sync scheduled__2024-10-29T19:00:00+00:00 [running]> on host 5558cd404a6f
[2024-10-29T21:09:36.887+0100] {taskinstance.py:1513} INFO - Exporting the following env vars:
AIRFLOW_CTX_DAG_OWNER=Admin
AIRFLOW_CTX_DAG_ID=airbyte_sync_dag
AIRFLOW_CTX_TASK_ID=trigger_airbyte_sync
AIRFLOW_CTX_EXECUTION_DATE=2024-10-29T19:00:00+00:00
AIRFLOW_CTX_TRY_NUMBER=2
AIRFLOW_CTX_DAG_RUN_ID=scheduled__2024-10-29T19:00:00+00:00
[2024-10-29T21:09:36.922+0100] {taskinstance.py:1772} ERROR - Task failed with exception
Traceback (most recent call last):
  File "/home/airflow/.local/lib/python3.7/site-packages/airflow/providers/airbyte/operators/airbyte.py", line 74, in execute
    job_object = self.hook.submit_sync_connection(connection_id=self.connection_id)
  File "/home/airflow/.local/lib/python3.7/site-packages/airflow/providers/airbyte/hooks/airbyte.py", line 95, in submit_sync_connection
    headers={"accept": "application/json"},
  File "/home/airflow/.local/lib/python3.7/site-packages/airflow/providers/http/hooks/http.py", line 130, in run
    session = self.get_conn(headers)
  File "/home/airflow/.local/lib/python3.7/site-packages/airflow/providers/http/hooks/http.py", line 84, in get_conn
    conn = self.get_connection(self.http_conn_id)
  File "/home/airflow/.local/lib/python3.7/site-packages/airflow/hooks/base.py", line 72, in get_connection
    conn = Connection.get_connection_from_secrets(conn_id)
  File "/home/airflow/.local/lib/python3.7/site-packages/airflow/models/connection.py", line 432, in get_connection_from_secrets
    raise AirflowNotFoundException(f"The conn_id `{conn_id}` isn't defined")
airflow.exceptions.AirflowNotFoundException: The conn_id `airbyte_conn` isn't defined
[2024-10-29T21:09:36.929+0100] {taskinstance.py:1327} INFO - Marking task as FAILED. dag_id=airbyte_sync_dag, task_id=trigger_airbyte_sync, execution_date=20241029T190000, start_date=20241029T200936, end_date=20241029T200936
[2024-10-29T21:09:36.945+0100] {standard_task_runner.py:105} ERROR - Failed to execute job 38 for task trigger_airbyte_sync (The conn_id `airbyte_conn` isn't defined; 8519)
[2024-10-29T21:09:36.984+0100] {local_task_job.py:159} INFO - Task exited with return code 1
[2024-10-29T21:09:37.053+0100] {taskinstance.py:2582} INFO - 0 downstream tasks scheduled from follow-on schedule check
